---
layout: post
title: "Django 1.5.1 のリリース (ジェネレーターに例外処理はダメ？)"
date: 2013-03-29 13:00:00 +0000
permalink: /jp/django-151
blog: jp
tags: django
render_with_liquid: false
locale: ja
---

Django 1.5.1 が昨日
[リリースされました](https://www.djangoproject.com/weblog/2013/mar/28/django-151/)
。リリース内容を見るて、クエリーセットにメモリリークの問題があったそうです。

## もともとのバグ

1.4 では、２回クエリーセットを解決すると、空な結果が返ってきて、前の結果がガーベージコレクションされない現象があったそうです ([バグ
\#19895](https://code.djangoproject.com/ticket/19895))

例えば:

```python
qs = MyModel.objects.all()
first = list(qs)
second = list(qs) # second は first と一緒だはずなのに、空になってしまう。。
```

1.5 ではこの問題に対して、
[修正された](https://github.com/gnosek/django/commit/ce057a7d488564e0ff6e8ec7daee2730fb2a8c01)
らしい。ただし、1.5 のリリース後にその修正はメモリリークを招いたことが分かった。

## メモリリーク

この問題は Python の動きに関係があるそうです。Django の開発者は [Python
のバグ](http://bugs.python.org/issue17468)
を登録していたんだけど、うちは社内で「それは既知の問題じゃね？」という話が出てきました。確かにこれは以前、
[石本さんが指摘してくれた](http://d.hatena.ne.jp/atsuoishimoto/20110227/1298817286)
問題です。恐らくこれは、Python のバグではなく、あまり知られてない仕様です。

## ジェネレータの中には例外処理はダメ？

Django
のクエリーセット例外処理をジェネレーターの中に行なっていた。石本さんの記事の様にジェネレーターの中に例外処理をすると、メモリが解放されないオブジェクトが出てきます。

以下の様なコードがあるとします。

```python
class MyObj(object):
    def __iter__(self):
        self._iter = iter(self.iterator())
        return iter(self._iter)

    def iterator(self):
        try:
            while True:
                yield 1
        except Exception:
            raise
```

ここでは、 `iterator()`
メソッドの中に例外処理があるので、このジェネレーターに参照があれば、ジェネレーターが使っているメモリが解放されない。

```python
>>> import gc
>>> class MyObj(object):
...     def __iter__(self):
...         self._iter = iter(self.iterator())
...         return iter(self._iter)
...     def iterator(self):
...         try:
...             while True:
...                 yield 1
...         except Exception:
...             raise
...
>>> gc.collect()
0
>>> i = next(iter(MyObj()))
>>> gc.collect()
4
>>> gc.garbage
[<generator object iterator at 0xb722d43c>]
```

## Django 1.5.1 の問題解決

最終的には、 1.5.1 では、
[この修正を取り除く](https://github.com/django/django/commit/b91067d9aa42e31d4375e00a703beaacdb30d608)
ようにして、 \#19895 は未解決状態に戻った。

こういう問題は、コードを見る時に、非常に気づきづらいけど、ジェネレーターをリークしないように、気をつけるしかないでしょうねぇ。ジェネレータを出来るだけ短く、例外処理や、
`with` を使わないようにしたほうがいいでしょう。
